2024-12-11 00:34:46,364 - root - INFO - Starting application...
2024-12-11 00:34:46,364 - database - INFO - Testing database connection...
2024-12-11 00:34:46,407 - database - INFO - Database connection successful!
2024-12-11 00:34:46,422 - root - INFO - Database tables verified
2024-12-11 00:35:55,574 - middleware.auth - ERROR - Auth error: name 'User' is not defined
2024-12-11 00:35:55,575 - middleware.auth - ERROR - Traceback (most recent call last):
  File "/home/guga-chavle/PycharmProjects/app/middleware/auth.py", line 129, in __call__
    user = db.query(User).filter(User.id == payload["user_id"]).first()
                    ^^^^
NameError: name 'User' is not defined

2024-12-11 00:35:55,575 - database - ERROR - Database session error: 
2024-12-11 00:35:55,576 - database - ERROR - Traceback (most recent call last):
  File "/home/guga-chavle/PycharmProjects/app/middleware/auth.py", line 129, in __call__
    user = db.query(User).filter(User.id == payload["user_id"]).first()
                    ^^^^
NameError: name 'User' is not defined

During handling of the above exception, another exception occurred:

Traceback (most recent call last):
  File "/home/guga-chavle/PycharmProjects/app/database.py", line 48, in get_db
    yield db
fastapi.exceptions.HTTPException

2024-12-11 00:36:44,883 - root - INFO - Shutting down application...
