2024-12-11 00:20:58,780 - root - INFO - Starting application...
2024-12-11 00:20:58,780 - database - INFO - Testing database connection...
2024-12-11 00:20:58,838 - database - INFO - Database connection successful!
2024-12-11 00:20:58,850 - root - INFO - Database tables verified
2024-12-11 00:21:20,919 - database - ERROR - Database session error: 
2024-12-11 00:21:20,920 - database - ERROR - Traceback (most recent call last):
  File "/home/guga-chavle/PycharmProjects/app/database.py", line 48, in get_db
    yield db
fastapi.exceptions.HTTPException

2024-12-11 00:22:36,743 - api.v1.endpoints.auth - ERROR - Signup error: 'rate_limit_minute' is an invalid keyword argument for User
2024-12-11 00:22:36,758 - api.v1.endpoints.auth - ERROR - Traceback (most recent call last):
  File "/home/guga-chavle/PycharmProjects/app/api/v1/endpoints/auth.py", line 87, in signup
    user = User(
           ^^^^^
  File "<string>", line 4, in __init__
  File "/home/guga-chavle/PycharmProjects/app/.venv/lib/python3.11/site-packages/sqlalchemy/orm/state.py", line 566, in _initialize_instance
    with util.safe_reraise():
  File "/home/guga-chavle/PycharmProjects/app/.venv/lib/python3.11/site-packages/sqlalchemy/util/langhelpers.py", line 146, in __exit__
    raise exc_value.with_traceback(exc_tb)
  File "/home/guga-chavle/PycharmProjects/app/.venv/lib/python3.11/site-packages/sqlalchemy/orm/state.py", line 564, in _initialize_instance
    manager.original_init(*mixed[1:], **kwargs)
  File "/home/guga-chavle/PycharmProjects/app/.venv/lib/python3.11/site-packages/sqlalchemy/orm/decl_base.py", line 2142, in _declarative_constructor
    raise TypeError(
TypeError: 'rate_limit_minute' is an invalid keyword argument for User

2024-12-11 00:22:36,758 - database - ERROR - Database session error: 
2024-12-11 00:22:36,759 - database - ERROR - Traceback (most recent call last):
  File "/home/guga-chavle/PycharmProjects/app/api/v1/endpoints/auth.py", line 87, in signup
    user = User(
           ^^^^^
  File "<string>", line 4, in __init__
  File "/home/guga-chavle/PycharmProjects/app/.venv/lib/python3.11/site-packages/sqlalchemy/orm/state.py", line 566, in _initialize_instance
    with util.safe_reraise():
  File "/home/guga-chavle/PycharmProjects/app/.venv/lib/python3.11/site-packages/sqlalchemy/util/langhelpers.py", line 146, in __exit__
    raise exc_value.with_traceback(exc_tb)
  File "/home/guga-chavle/PycharmProjects/app/.venv/lib/python3.11/site-packages/sqlalchemy/orm/state.py", line 564, in _initialize_instance
    manager.original_init(*mixed[1:], **kwargs)
  File "/home/guga-chavle/PycharmProjects/app/.venv/lib/python3.11/site-packages/sqlalchemy/orm/decl_base.py", line 2142, in _declarative_constructor
    raise TypeError(
TypeError: 'rate_limit_minute' is an invalid keyword argument for User

During handling of the above exception, another exception occurred:

Traceback (most recent call last):
  File "/home/guga-chavle/PycharmProjects/app/database.py", line 48, in get_db
    yield db
fastapi.exceptions.HTTPException

2024-12-11 00:22:37,754 - api.v1.endpoints.auth - ERROR - Signup error: 'rate_limit_minute' is an invalid keyword argument for User
2024-12-11 00:22:37,755 - api.v1.endpoints.auth - ERROR - Traceback (most recent call last):
  File "/home/guga-chavle/PycharmProjects/app/api/v1/endpoints/auth.py", line 87, in signup
    user = User(
           ^^^^^
  File "<string>", line 4, in __init__
  File "/home/guga-chavle/PycharmProjects/app/.venv/lib/python3.11/site-packages/sqlalchemy/orm/state.py", line 566, in _initialize_instance
    with util.safe_reraise():
  File "/home/guga-chavle/PycharmProjects/app/.venv/lib/python3.11/site-packages/sqlalchemy/util/langhelpers.py", line 146, in __exit__
    raise exc_value.with_traceback(exc_tb)
  File "/home/guga-chavle/PycharmProjects/app/.venv/lib/python3.11/site-packages/sqlalchemy/orm/state.py", line 564, in _initialize_instance
    manager.original_init(*mixed[1:], **kwargs)
  File "/home/guga-chavle/PycharmProjects/app/.venv/lib/python3.11/site-packages/sqlalchemy/orm/decl_base.py", line 2142, in _declarative_constructor
    raise TypeError(
TypeError: 'rate_limit_minute' is an invalid keyword argument for User

2024-12-11 00:22:37,755 - database - ERROR - Database session error: 
2024-12-11 00:22:37,756 - database - ERROR - Traceback (most recent call last):
  File "/home/guga-chavle/PycharmProjects/app/api/v1/endpoints/auth.py", line 87, in signup
    user = User(
           ^^^^^
  File "<string>", line 4, in __init__
  File "/home/guga-chavle/PycharmProjects/app/.venv/lib/python3.11/site-packages/sqlalchemy/orm/state.py", line 566, in _initialize_instance
    with util.safe_reraise():
  File "/home/guga-chavle/PycharmProjects/app/.venv/lib/python3.11/site-packages/sqlalchemy/util/langhelpers.py", line 146, in __exit__
    raise exc_value.with_traceback(exc_tb)
  File "/home/guga-chavle/PycharmProjects/app/.venv/lib/python3.11/site-packages/sqlalchemy/orm/state.py", line 564, in _initialize_instance
    manager.original_init(*mixed[1:], **kwargs)
  File "/home/guga-chavle/PycharmProjects/app/.venv/lib/python3.11/site-packages/sqlalchemy/orm/decl_base.py", line 2142, in _declarative_constructor
    raise TypeError(
TypeError: 'rate_limit_minute' is an invalid keyword argument for User

During handling of the above exception, another exception occurred:

Traceback (most recent call last):
  File "/home/guga-chavle/PycharmProjects/app/database.py", line 48, in get_db
    yield db
fastapi.exceptions.HTTPException

2024-12-11 00:22:51,057 - database - ERROR - Database session error: 
2024-12-11 00:22:51,057 - database - ERROR - Traceback (most recent call last):
  File "/home/guga-chavle/PycharmProjects/app/database.py", line 48, in get_db
    yield db
fastapi.exceptions.HTTPException

2024-12-11 00:23:21,474 - database - ERROR - Database session error: 
2024-12-11 00:23:21,475 - database - ERROR - Traceback (most recent call last):
  File "/home/guga-chavle/PycharmProjects/app/database.py", line 48, in get_db
    yield db
fastapi.exceptions.HTTPException

2024-12-11 00:26:09,073 - middleware.auth - ERROR - Auth error: name 'User' is not defined
2024-12-11 00:26:09,074 - middleware.auth - ERROR - Traceback (most recent call last):
  File "/home/guga-chavle/PycharmProjects/app/middleware/auth.py", line 129, in __call__
    user = db.query(User).filter(User.id == payload["user_id"]).first()
                    ^^^^
NameError: name 'User' is not defined

2024-12-11 00:26:09,074 - database - ERROR - Database session error: 
2024-12-11 00:26:09,075 - database - ERROR - Traceback (most recent call last):
  File "/home/guga-chavle/PycharmProjects/app/middleware/auth.py", line 129, in __call__
    user = db.query(User).filter(User.id == payload["user_id"]).first()
                    ^^^^
NameError: name 'User' is not defined

During handling of the above exception, another exception occurred:

Traceback (most recent call last):
  File "/home/guga-chavle/PycharmProjects/app/database.py", line 48, in get_db
    yield db
fastapi.exceptions.HTTPException

2024-12-11 00:28:01,132 - root - INFO - Shutting down application...
